<?xml version="1.0" encoding="utf-8"?>
<!-- This URDF was automatically created by SolidWorks to URDF Exporter! Originally created by Stephen Brawner (brawner@gmail.com) 
     Commit Version: 1.6.0-1-g15f4949  Build Version: 1.6.7594.29634
     For more information, please see http://wiki.ros.org/sw_urdf_exporter -->
<robot xmlns:xacro="http://ros.org/wiki/xacro" name="espdrone">
<xacro:include filename="$(find espdrone_driver)/urdf/gazebo_plugin.xacro" />
<xacro:arg name="drone_index" default="1" />

	<material name = "black">
		<color rgba="0 0 0 1"/>
	</material>
	<material name = "red">
		<color rgba="1 0 0 1"/>
	</material>
	<material name = "green">
		<color rgba="0 1 0 1"/>
	</material>
	<material name = "blue">
		<color rgba="0 0 1 1"/>
	</material>
	<material name = "yellow">
		<color rgba="1 1 0 1"/>
	</material>
	<material name = "white">
		<color rgba="1 1 1 1"/>
	</material>
  <link
    name="base_link_$(arg drone_index)">
    <inertial>
      <origin
        xyz="0.00273534176117628 0.000310104344010811 -0.00921683696721233"
        rpy="0 0 0" />
      <mass
        value="0.005" />
      <inertia
        ixx="5.74138315905152E-06"
        ixy="1.92834480377476E-10"
        ixz="5.23128068754328E-09"
        iyy="5.59597494658092E-06"
        iyz="-4.57300185110961E-11"
        izz="1.07544652567121E-05" />
    </inertial>
    <visual>
      <origin
        xyz="0 0 0"
        rpy="0 0 0" />
      <geometry>
        <mesh
          filename="package://espdrone_driver/meshes/base_link.STL" />
      </geometry>
      <material
        name="white">
<!--
        <color
          rgba="1 1 1 1" />  -->
      </material>
    </visual>
    <collision>
      <origin
        xyz="0 0 0"
        rpy="0 0 0" />
      <geometry>
        <mesh
          filename="package://espdrone_driver/meshes/base_link.STL" />
      </geometry>
    </collision>
  </link>
  <link
    name="FR_link_$(arg drone_index)">
    <inertial>
      <origin
        xyz="-2.31951351493953E-06 4.75087751597436E-07 0.00518072305319314"
        rpy="0 0 0" />
      <mass
        value="0.000170761508616818" />
      <inertia
        ixx="4.6755014059117E-09"
        ixy="2.32513739562609E-12"
        ixz="5.71859115287334E-14"
        iyy="4.6758546712305E-09"
        iyz="-1.22257798998163E-12"
        izz="7.47442921255212E-09" />
    </inertial>
    <visual>
      <origin
        xyz="0 0 0"
        rpy="0 0 0" />
      <geometry>
        <mesh
          filename="package://espdrone_driver/meshes/FR_link.STL" />
      </geometry>
      <material
        name="red">
      </material>
    </visual>
    <collision>
      <origin
        xyz="0 0 0"
        rpy="0 0 0" />
      <geometry>
        <mesh
          filename="package://espdrone_driver/meshes/FR_link.STL" />
      </geometry>
    </collision>
  </link>
  <joint
    name="FR_joint_$(arg drone_index)"
    type="continuous">
    <origin
      xyz="0.0257492934362308 -0.0229194400056349 -0.00749999999999998"
      rpy="0 0 0" />
    <parent
      link="base_link_$(arg drone_index)" />
    <child
      link="FR_link_$(arg drone_index)" />
    <axis
      xyz="0 0 1" />
  </joint>
  <link
    name="BR_link_$(arg drone_index)">
    <inertial>
      <origin
        xyz="-8.1600715337582E-08 -1.72083848282156E-08 0.00522367470183978"
        rpy="0 0 0" />
      <mass
        value="0.00018061996609001" />
      <inertia
        ixx="5.31750986815953E-09"
        ixy="-5.16314476983196E-15"
        ixz="9.66455527233112E-16"
        iyy="5.31754307596758E-09"
        iyz="1.26078782972358E-14"
        izz="8.76724562794108E-09" />
    </inertial>
    <visual>
      <origin
        xyz="0 0 0"
        rpy="0 0 0" />
      <geometry>
        <mesh
          filename="package://espdrone_driver/meshes/BR_link.STL" />
      </geometry>
      <material
        name="green">
      </material>
    </visual>
    <collision>
      <origin
        xyz="0 0 0"
        rpy="0 0 0" />
      <geometry>
        <mesh
          filename="package://espdrone_driver/meshes/BR_link.STL" />
      </geometry>
    </collision>
  </link>
  <joint
    name="BR_joint_$(arg drone_index)"
    type="continuous">
    <origin
      xyz="-0.0191761230425737 -0.0229194400056349 -0.00749999999999998"
      rpy="0 0 0" />
    <parent
      link="base_link_$(arg drone_index)" />
    <child
      link="BR_link_$(arg drone_index)" />
    <axis
      xyz="0 0 -1" />
  </joint>
  <link
    name="BL_link_$(arg drone_index)">
    <inertial>
      <origin
        xyz="2.38010113044621E-06 -1.38898463120096E-07 0.00518072472347876"
        rpy="0 0 0" />
      <mass
        value="0.000170760818462595" />
      <inertia
        ixx="4.67479351796267E-09"
        ixy="2.15642873143842E-12"
        ixz="-2.37844642269294E-13"
        iyy="4.67652605370328E-09"
        iyz="1.1980550310324E-12"
        izz="7.47439160543409E-09" />
    </inertial>
    <visual>
      <origin
        xyz="0 0 0"
        rpy="0 0 0" />
      <geometry>
        <mesh
          filename="package://espdrone_driver/meshes/BL_link.STL" />
      </geometry>
      <material
        name="red">
      </material>
    </visual>
    <collision>
      <origin
        xyz="0 0 0"
        rpy="0 0 0" />
      <geometry>
        <mesh
          filename="package://espdrone_driver/meshes/BL_link.STL" />
      </geometry>
    </collision>
  </link>
  <joint
    name="BL_joint_$(arg drone_index)"
    type="continuous">
    <origin
      xyz="-0.0191761230425737 0.0236734441396914 -0.00749999999999998"
      rpy="0 0 0" />
    <parent
      link="base_link_$(arg drone_index)" />
    <child
      link="BL_link_$(arg drone_index)" />
    <axis
      xyz="0 0 1" />
  </joint>
  <link
    name="FL_link_$(arg drone_index)">
    <inertial>
      <origin
        xyz="3.80231074056936E-08 6.12791400643464E-08 0.00522368229657419"
        rpy="0 0 0" />
      <mass
        value="0.000180619348875049" />
      <inertia
        ixx="5.31750546690808E-09"
        ixy="-1.73067916761242E-14"
        ixz="7.88814557746303E-15"
        iyy="5.31749812438277E-09"
        iyz="-1.38442562224496E-14"
        izz="8.7672030898276E-09" />
    </inertial>
    <visual>
      <origin
        xyz="0 0 0"
        rpy="0 0 0" />
      <geometry>
        <mesh
          filename="package://espdrone_driver/meshes/FL_link.STL" />
      </geometry>
      <material
        name="green">
      </material>
    </visual>
    <collision>
      <origin
        xyz="0 0 0"
        rpy="0 0 0" />
      <geometry>
        <mesh
          filename="package://espdrone_driver/meshes/FL_link.STL" />
      </geometry>
    </collision>
  </link>
  <joint
    name="FL_joint_$(arg drone_index)"
    type="continuous">
    <origin
      xyz="0.0257492934362308 0.0236734441396913 -0.00749999999999998"
      rpy="0 0 0" />
    <parent
      link="base_link_$(arg drone_index)" />
    <child
      link="FL_link_$(arg drone_index)" />
    <axis
      xyz="0 0 -1" />
  </joint>
  <link
    name="camera_link_$(arg drone_index)">
    <inertial>
      <origin
        xyz="-0.0053534367867157 5.60012155745304E-08 0.00209997888295398"
        rpy="0 0 0" />
      <mass
        value="0.000254844473496216" />
      <inertia
        ixx="2.52700381545915E-09"
        ixy="1.04192854320719E-17"
        ixz="-1.79532031326891E-15"
        iyy="1.43070118000395E-09"
        iyz="4.34605630270488E-15"
        izz="1.43143838579387E-09" />
    </inertial>
    <visual>
      <origin
        xyz="0 0 0"
        rpy="0 0 0" />
      <geometry>
        <mesh
          filename="package://espdrone_driver/meshes/camera_link.STL" />
      </geometry>
      <material
        name="black">

      </material>
    </visual>
    <collision>
      <origin
        xyz="0 0 0"
        rpy="0 0 0" />
      <geometry>
        <mesh
          filename="package://espdrone_driver/meshes/camera_link.STL" />
      </geometry>
    </collision>
  </link>
  <joint
    name="camera_joint_$(arg drone_index)"
    type="fixed">
    <origin
      xyz="0.0303459244383208 4.86220498038051E-05 -0.00399998047147145"
      rpy="0 0 0" />
    <parent
      link="base_link_$(arg drone_index)" />
    <child
      link="camera_link_$(arg drone_index)" />
    <axis
      xyz="0 0 0" />
  </joint>
  <link
    name="pcb_link_$(arg drone_index)">
    <inertial>
      <origin
        xyz="0.00022494415763474 6.19688084457087E-06 0.000796325853178126"
        rpy="0 0 0" />
      <mass
        value="0.00172915830500381" />
      <inertia
        ixx="4.79318130962085E-08"
        ixy="1.92841414340502E-10"
        ixz="3.18428765368808E-10"
        iyy="2.05435520095623E-07"
        iyz="-4.50719451470362E-11"
        izz="2.51263861490945E-07" />
    </inertial>
    <visual>
      <origin
        xyz="0 0 0"
        rpy="0 0 0" />
      <geometry>
        <mesh
          filename="package://espdrone_driver/meshes/pcb_link_visual.STL" />
      </geometry>
      <material
        name="yellow">
      </material>
    </visual>
    <collision>
      <origin
        xyz="0 0 0"
        rpy="0 0 0" />
      <geometry>
        <mesh
          filename="package://espdrone_driver/meshes/pcb_link.STL" />
      </geometry>
    </collision>
  </link>
  <joint
    name="pcb_joint_$(arg drone_index)"
    type="fixed">
    <origin
      xyz="0 0 0"
      rpy="0 0 0" />
    <parent
      link="base_link_$(arg drone_index)" />
    <child
      link="pcb_link_$(arg drone_index)" />
    <axis
      xyz="0 0 0" />
  </joint>
  <link
    name="pcb_plate_link_$(arg drone_index)">
    <inertial>
      <origin
        xyz="0.00022495550644493 6.20412368211587E-06 0.000796328088142936"
        rpy="0 0 0" />
      <mass
        value="0.00172915383636057" />
      <inertia
        ixx="4.79319207989059E-08"
        ixy="1.93051673791148E-10"
        ixz="3.1844298586841E-10"
        iyy="2.05435513643283E-07"
        iyz="-4.50628996738981E-11"
        izz="2.51263977451861E-07" />
    </inertial>
    <visual>
      <origin
        xyz="0 0 0"
        rpy="0 0 0" />
      <geometry>
        <mesh
          filename="package://espdrone_driver/meshes/pcb_plate_link.STL" />
      </geometry>
      <material
        name="blue">
      </material>
    </visual>
    <collision>
      <origin
        xyz="0 0 0"
        rpy="0 0 0" />
      <geometry>
        <mesh
          filename="package://espdrone_driver/meshes/pcb_plate_link.STL" />
      </geometry>
    </collision>
  </link>
  <joint
    name="pcb_plate_joint_$(arg drone_index)"
    type="fixed">
    <origin
      xyz="0 0 0"
      rpy="0 0 0" />
    <parent
      link="base_link_$(arg drone_index)" />
    <child
      link="pcb_plate_link_$(arg drone_index)" />
    <axis
      xyz="0 0 0" />
  </joint>

  <!-- transmission -->
  <transmission name="FL_trans_$(arg drone_index)">
    <type>transmission_interface/SimpleTransmission</type>
    <joint name="FL_joint_$(arg drone_index)">
      <hardwareInterface>hardware_interface/VelocityJointInterface</hardwareInterface>
    </joint>
    <actuator name="FL_motor_$(arg drone_index)">
      <hardwareInterface>hardware_interface/VelocityJointInterface</hardwareInterface>
      <mechanicalReduction>1</mechanicalReduction>
    </actuator>
  </transmission>

  <transmission name="FR_trans_$(arg drone_index)">
    <type>transmission_interface/SimpleTransmission</type>
    <joint name="FR_joint_$(arg drone_index)">
      <hardwareInterface>hardware_interface/VelocityJointInterface</hardwareInterface>
    </joint>
    <actuator name="FR_motor_$(arg drone_index)">
      <hardwareInterface>hardware_interface/VelocityJointInterface</hardwareInterface>
      <mechanicalReduction>1</mechanicalReduction>
    </actuator>
  </transmission>

  <transmission name="BR_trans_$(arg drone_index)">
    <type>transmission_interface/SimpleTransmission</type>
    <joint name="BR_joint_$(arg drone_index)">
      <hardwareInterface>hardware_interface/VelocityJointInterface</hardwareInterface>
    </joint>
    <actuator name="BR_motor_$(arg drone_index)">
      <hardwareInterface>hardware_interface/VelocityJointInterface</hardwareInterface>
      <mechanicalReduction>1</mechanicalReduction>
    </actuator>
  </transmission>

  <transmission name="BL_trans_$(arg drone_index)">
    <type>transmission_interface/SimpleTransmission</type>
    <joint name="BL_joint_$(arg drone_index)">
      <hardwareInterface>hardware_interface/VelocityJointInterface</hardwareInterface>
    </joint>
    <actuator name="BL_motor_$(arg drone_index)">
      <hardwareInterface>hardware_interface/VelocityJointInterface</hardwareInterface>
      <mechanicalReduction>1</mechanicalReduction>
    </actuator>
  </transmission>
</robot>
