<?xml version="1.0" encoding="utf-8"?>
<!-- This URDF was automatically created by SolidWorks to URDF Exporter! Originally created by Stephen Brawner (brawner@gmail.com) 
     Commit Version: 1.6.0-1-g15f4949  Build Version: 1.6.7594.29634
     For more information, please see http://wiki.ros.org/sw_urdf_exporter -->
<robot xmlns:xacro="http://ros.org/wiki/xacro" name="espdrone">
<xacro:include filename="$(find espdrone_driver)/urdf/gazebo_plugin.xacro" />
<xacro:arg name="drone_index" default="1" />

	<material name = "black">
		<color rgba="0 0 0 1"/>
	</material>
	<material name = "red">
		<color rgba="1 0 0 1"/>
	</material>
	<material name = "green">
		<color rgba="0 1 0 1"/>
	</material>
	<material name = "blue">
		<color rgba="0 0 1 1"/>
	</material>
	<material name = "yellow">
		<color rgba="1 1 0 1"/>
	</material>
	<material name = "white">
		<color rgba="1 1 1 1"/>
	</material>
  <link
    name="base_link_$(arg drone_index)">
    <inertial>
      <origin
<<<<<<< HEAD
        xyz="-8.4922E-05 -5.1889E-06 -0.012067"
=======
        xyz="1.1546E-17 -9.6133E-19 1.2281E-18"
>>>>>>> 6b9c0dd6c270949edfab78a9c1be2bbdc6c511fc
        rpy="0 0 0" />
      <mass
        value="0.022" />
      <inertia
        ixx="5.6903E-06"
        ixy="-1.7344E-15"
        ixz="4.9169E-09"
        iyy="5.3876E-06"
        iyz="-1.6461E-13"
        izz="1.0498E-05" />
    </inertial>
    <visual>
      <origin
        xyz="0 0 0"
        rpy="0 0 0" />
      <geometry>
        <mesh
          filename="package://espdrone_driver/meshes/base_link.STL" />
      </geometry>
      <material
        name="white">
<!--
        <color
          rgba="1 1 1 1" />  -->
      </material>
    </visual>
    <collision>
      <origin
        xyz="0 0 0"
        rpy="0 0 0" />
      <geometry>
        <mesh
          filename="package://espdrone_driver/meshes/base_link.STL" />
      </geometry>
    </collision>
  </link>
  <link
    name="FR_link_$(arg drone_index)">
    <inertial>
      <origin
<<<<<<< HEAD
        xyz="2.19386060301349E-06 -9.68362298764402E-07 0.00323605128895478"
=======
        xyz="2.1939E-06 -9.6836E-07 0.0032361"
>>>>>>> 6b9c0dd6c270949edfab78a9c1be2bbdc6c511fc
        rpy="0 0 0" />
      <mass
        value="0.000170761508616818" />
      <inertia
<<<<<<< HEAD
        ixx="4.67644382978833E-09"
        ixy="2.19394380780143E-12"
        ixz="2.02295621851495E-13"
        iyy="4.67485384007775E-09"
        iyz="1.20316619967357E-12"
        izz="7.47437053355022E-09" />
=======
        ixx="4.6764E-09"
        ixy="2.1939E-12"
        ixz="2.023E-13"
        iyy="4.6749E-09"
        iyz="1.2032E-12"
        izz="7.4744E-09" />
>>>>>>> 6b9c0dd6c270949edfab78a9c1be2bbdc6c511fc
    </inertial>
    <visual>
      <origin
        xyz="0 0 0"
        rpy="0 0 0" />
      <geometry>
        <mesh
          filename="package://espdrone_driver/meshes/FR_link.STL" />
      </geometry>
      <material
        name="red">
      </material>
    </visual>
    <collision>
      <origin
        xyz="0 0 0"
        rpy="0 0 0" />
      <geometry>
        <mesh
          filename="package://espdrone_driver/meshes/FR_link.STL" />
      </geometry>
    </collision>
  </link>
  <joint
    name="FR_joint_$(arg drone_index)"
    type="continuous">
    <origin
<<<<<<< HEAD
      xyz="0.022469 -0.02329 -0.0053847"
=======
      xyz="0.022554 -0.023285 0.0066819"
>>>>>>> 6b9c0dd6c270949edfab78a9c1be2bbdc6c511fc
      rpy="0 0 0.079117" />
    <parent
      link="base_link_$(arg drone_index)" />
    <child
      link="FR_link_$(arg drone_index)" />
    <axis
      xyz="0 0 1" />
  </joint>
  <link
    name="BR_link_$(arg drone_index)">
    <inertial>
      <origin
<<<<<<< HEAD
        xyz="-7.56440794238977E-08 -2.88324636596449E-08 0.00327154784152278"
=======
        xyz="-5.8103E-08 1.0092E-07 0.0032716"
>>>>>>> 6b9c0dd6c270949edfab78a9c1be2bbdc6c511fc
        rpy="0 0 0" />
      <mass
        value="0.00018062" />
      <inertia
<<<<<<< HEAD
        ixx="5.31752179818623E-09"
        ixy="-9.13133512897449E-15"
        ixz="8.05001778605325E-16"
        iyy="5.31754756765752E-09"
        iyz="1.22536182980167E-14"
        izz="8.76725630082634E-09" />
=======
        ixx="5.3175E-09"
        ixy="1.0972E-14"
        ixz="9.8184E-15"
        iyy="5.3175E-09"
        iyz="2.1136E-14"
        izz="8.7672E-09" />
>>>>>>> 6b9c0dd6c270949edfab78a9c1be2bbdc6c511fc
    </inertial>
    <visual>
      <origin
        xyz="0 0 0"
        rpy="0 0 0" />
      <geometry>
        <mesh
          filename="package://espdrone_driver/meshes/BR_link.STL" />
      </geometry>
      <material
        name="green">
      </material>
    </visual>
    <collision>
      <origin
        xyz="0 0 0"
        rpy="0 0 0" />
      <geometry>
        <mesh
          filename="package://espdrone_driver/meshes/BR_link.STL" />
      </geometry>
    </collision>
  </link>
  <joint
    name="BR_joint_$(arg drone_index)"
    type="continuous">
    <origin
      xyz="-0.022456 -0.02329 -0.0057529"
      rpy="0 0 0" />
    <parent
      link="base_link_$(arg drone_index)" />
    <child
      link="BR_link_$(arg drone_index)" />
    <axis
      xyz="0 0 -1" />
  </joint>
  <link
    name="BL_link_$(arg drone_index)">
    <inertial>
      <origin
        xyz="2.1712E-06 -9.7472E-07 0.0032361"
        rpy="0 0 0" />
      <mass
        value="0.00017076" />
      <inertia
        ixx="4.6765E-09"
        ixy="2.1871E-12"
        ixz="2.0463E-13"
        iyy="4.6749E-09"
        iyz="1.2035E-12"
        izz="7.4744E-09" />
    </inertial>
    <visual>
      <origin
        xyz="0 0 0"
        rpy="0 0 0" />
      <geometry>
        <mesh
          filename="package://espdrone_driver/meshes/BL_link.STL" />
      </geometry>
      <material
        name="red">
      </material>
    </visual>
    <collision>
      <origin
        xyz="0 0 0"
        rpy="0 0 0" />
      <geometry>
        <mesh
          filename="package://espdrone_driver/meshes/BL_link.STL" />
      </geometry>
    </collision>
  </link>
  <joint
    name="BL_joint_$(arg drone_index)"
    type="continuous">
    <origin
      xyz="-0.022456 0.023302 -0.0057325"
      rpy="0 0 0" />
    <parent
      link="base_link_$(arg drone_index)" />
    <child
      link="BL_link_$(arg drone_index)" />
    <axis
      xyz="0 0 1" />
  </joint>
  <link
    name="FL_link_$(arg drone_index)">
    <inertial>
      <origin
        xyz="-8.62749092375714E-08 -3.52031720891877E-08 0.00327155903890045"
        rpy="0 0 0" />
      <mass
        value="0.000180619564419041" />
      <inertia
        ixx="5.31748216155639E-09"
        ixy="-9.62023286312814E-15"
        ixz="-5.75245567527913E-15"
        iyy="5.31751999949103E-09"
        iyz="1.16455364824185E-14"
        izz="8.76719916078178E-09" />
    </inertial>
    <visual>
      <origin
        xyz="0 0 0"
        rpy="0 0 0" />
      <geometry>
        <mesh
          filename="package://espdrone_driver/meshes/FL_link.STL" />
      </geometry>
      <material
        name="green">
      </material>
    </visual>
    <collision>
      <origin
        xyz="0 0 0"
        rpy="0 0 0" />
      <geometry>
        <mesh
          filename="package://espdrone_driver/meshes/FL_link.STL" />
      </geometry>
    </collision>
  </link>
  <joint
    name="FL_joint_$(arg drone_index)"
    type="continuous">
    <origin
      xyz="0.022469 0.023302 -0.0055374"
      rpy="0 0 0" />
    <parent
      link="base_link_$(arg drone_index)" />
    <child
      link="FL_link_$(arg drone_index)" />
    <axis
      xyz="0 0 -1" />
  </joint>
  <link
    name="camera_link_$(arg drone_index)">
    <inertial>
      <origin
        xyz="0.0033966 -3.605E-09 0.0048462"
        rpy="0 0 0" />
      <mass
        value="0.00025484" />
      <inertia
        ixx="2.527E-09"
        ixy="-1.7953E-15"
        ixz="-1.0419E-17"
        iyy="1.4314E-09"
        iyz="-4.3461E-15"
        izz="1.4307E-09" />
    </inertial>
    <visual>
      <origin
        xyz="0 0 0"
        rpy="0 0 0" />
      <geometry>
        <mesh
          filename="package://espdrone_driver/meshes/camera_link.STL" />
      </geometry>
      <material
        name="black">
      </material>
    </visual>
    <collision>
      <origin
        xyz="0 0 0"
        rpy="0 0 0" />
      <geometry>
        <mesh
          filename="package://espdrone_driver/meshes/camera_link.STL" />
      </geometry>
    </collision>
  </link>
  <joint
    name="camera_joint_$(arg drone_index)"
    type="fixed">
    <origin
      xyz="0.019443 0 -0.010256"
      rpy="0 0 0" />
    <parent
      link="base_link_$(arg drone_index)" />
    <child
      link="camera_link_$(arg drone_index)" />
    <axis
      xyz="0 0 0" />
  </joint>

  <link
    name="pcb_link_$(arg drone_index)">
    <inertial>
      <origin
        xyz="-0.0193719085455067 0.00524912091328601 0.00739049052905435"
        rpy="0 0 0" />
      <mass
        value="0.00172915830500381" />
      <inertia
        ixx="4.22200930314278E-08"
        ixy="1.93579463454107E-10"
        ixz="3.09029969679613E-10"
        iyy="1.81602856101841E-07"
        iyz="-4.40021046694622E-11"
        izz="2.22279136875617E-07" />
    </inertial>
    <visual>
      <origin
        xyz="0 0 0"
        rpy="0 0 0" />
      <geometry>
        <mesh
          filename="package://espdrone_driver/meshes/pcb_link_visual.STL" />
      </geometry>
      <material
        name="yellow">
      </material>
    </visual>
    <collision>
      <origin
        xyz="0 0 0"
        rpy="0 0 0" />
      <geometry>
        <mesh
          filename="package://espdrone_driver/meshes/pcb_link.STL" />
      </geometry>
    </collision>
  </link>

  <joint
    name="pcb_joint_$(arg drone_index)"
    type="fixed">
    <origin
      xyz="0.017473 -0.0052357 -0.0077544"
      rpy="0 0 0" />
    <parent
      link="base_link_$(arg drone_index)" />
    <child
      link="pcb_link_$(arg drone_index)" />
    <axis
      xyz="0 0 0" />
  </joint>

  <link
    name="pcb_plate_link_$(arg drone_index)">
    <inertial>
      <origin
        xyz="-0.0193719085455067 0.00524912091328601 0.00739049052905435"
        rpy="0 0 0" />
      <mass
        value="0.00153077609060128" />
      <inertia
        ixx="4.22200930314278E-08"
        ixy="1.93579463454107E-10"
        ixz="3.09029969679613E-10"
        iyy="1.81602856101841E-07"
        iyz="-4.40021046694622E-11"
        izz="2.22279136875617E-07" />
    </inertial>
    <visual>
      <origin
        xyz="0 0 0"
        rpy="0 0 0" />
      <geometry>
        <mesh
          filename="package://espdrone_driver/meshes/pcb_plate_link.STL" />
      </geometry>
      <material
        name="blue">
      </material>
    </visual>
    <collision>
      <origin
        xyz="0 0 0"
        rpy="0 0 0" />
      <geometry>
        <mesh
          filename="package://espdrone_driver/meshes/pcb_plate_link.STL" />
      </geometry>
    </collision>
  </link>

  <joint
    name="pcb_plate_joint_$(arg drone_index)"
    type="fixed">
    <origin
      xyz="0.017473 -0.0052357 -0.0077544"
      rpy="0 0 0" />
    <parent
      link="base_link" />
    <child
      link="pcb_plate_link" />
    <axis
      xyz="0 0.63613 0.77159" />
  </joint>

  <!-- transmission -->
  <transmission name="FL_trans_$(arg drone_index)">
    <type>transmission_interface/SimpleTransmission</type>
    <joint name="FL_joint_$(arg drone_index)">
      <hardwareInterface>hardware_interface/VelocityJointInterface</hardwareInterface>
    </joint>
    <actuator name="FL_motor_$(arg drone_index)">
      <hardwareInterface>hardware_interface/VelocityJointInterface</hardwareInterface>
      <mechanicalReduction>1</mechanicalReduction>
    </actuator>
  </transmission>

  <transmission name="FR_trans_$(arg drone_index)">
    <type>transmission_interface/SimpleTransmission</type>
    <joint name="FR_joint_$(arg drone_index)">
      <hardwareInterface>hardware_interface/VelocityJointInterface</hardwareInterface>
    </joint>
    <actuator name="FR_motor_$(arg drone_index)">
      <hardwareInterface>hardware_interface/VelocityJointInterface</hardwareInterface>
      <mechanicalReduction>1</mechanicalReduction>
    </actuator>
  </transmission>

  <transmission name="BR_trans_$(arg drone_index)">
    <type>transmission_interface/SimpleTransmission</type>
    <joint name="BR_joint_$(arg drone_index)">
      <hardwareInterface>hardware_interface/VelocityJointInterface</hardwareInterface>
    </joint>
    <actuator name="BR_motor_$(arg drone_index)">
      <hardwareInterface>hardware_interface/VelocityJointInterface</hardwareInterface>
      <mechanicalReduction>1</mechanicalReduction>
    </actuator>
  </transmission>

  <transmission name="BL_trans_$(arg drone_index)">
    <type>transmission_interface/SimpleTransmission</type>
    <joint name="BL_joint_$(arg drone_index)">
      <hardwareInterface>hardware_interface/VelocityJointInterface</hardwareInterface>
    </joint>
    <actuator name="BL_motor_$(arg drone_index)">
      <hardwareInterface>hardware_interface/VelocityJointInterface</hardwareInterface>
      <mechanicalReduction>1</mechanicalReduction>
    </actuator>
  </transmission>
</robot>
